fatal: Not a valid object name d9aed99c6d022005ee15a8ec50deab391911f600
Traceback (most recent call last):
  File "/Users/bohrok/Documents/replication-kit-2020-line-validation/gitparse.py", line 426, in <module>
    changes = Changes(repo_path, commit)
  File "/Users/bohrok/Documents/replication-kit-2020-line-validation/gitparse.py", line 254, in __init__
    ) = get_changes(diff, repo_path)
  File "/Users/bohrok/Documents/replication-kit-2020-line-validation/gitparse.py", line 205, in get_changes
    line_num_old, line_num_new = get_changed_lines(
  File "/Users/bohrok/Documents/replication-kit-2020-line-validation/gitparse.py", line 169, in get_changed_lines
    a_blob_str = subprocess.check_output(
  File "/Users/bohrok/.pyenv/versions/3.9.7/lib/python3.9/subprocess.py", line 424, in check_output
    return run(*popenargs, stdout=PIPE, timeout=timeout, check=True,
  File "/Users/bohrok/.pyenv/versions/3.9.7/lib/python3.9/subprocess.py", line 528, in run
    raise CalledProcessError(retcode, process.args,
subprocess.CalledProcessError: Command 'git cat-file -p d9aed99c6d022005ee15a8ec50deab391911f600' returned non-zero exit status 128.
위에 이거 systemds error 임